[2023-10-08T17:08:58.886+0000] {taskinstance.py:1157} INFO - Dependencies all met for dep_context=non-requeueable deps ti=<TaskInstance: BigQuery_dag.Fetch_data_API manual__2023-10-08T17:08:52.450884+00:00 [queued]>
[2023-10-08T17:08:58.920+0000] {taskinstance.py:1157} INFO - Dependencies all met for dep_context=requeueable deps ti=<TaskInstance: BigQuery_dag.Fetch_data_API manual__2023-10-08T17:08:52.450884+00:00 [queued]>
[2023-10-08T17:08:58.921+0000] {taskinstance.py:1359} INFO - Starting attempt 1 of 1
[2023-10-08T17:08:58.992+0000] {taskinstance.py:1380} INFO - Executing <Task(PythonOperator): Fetch_data_API> on 2023-10-08 17:08:52.450884+00:00
[2023-10-08T17:08:59.005+0000] {standard_task_runner.py:57} INFO - Started process 166 to run task
[2023-10-08T17:08:59.034+0000] {standard_task_runner.py:84} INFO - Running: ['airflow', 'tasks', 'run', 'BigQuery_dag', 'Fetch_data_API', 'manual__2023-10-08T17:08:52.450884+00:00', '--job-id', '6', '--raw', '--subdir', 'DAGS_FOLDER/BigQuery_dag.py', '--cfg-path', '/tmp/tmpyo9vhlpv']
[2023-10-08T17:08:59.040+0000] {standard_task_runner.py:85} INFO - Job 6: Subtask Fetch_data_API
[2023-10-08T17:08:59.595+0000] {task_command.py:415} INFO - Running <TaskInstance: BigQuery_dag.Fetch_data_API manual__2023-10-08T17:08:52.450884+00:00 [running]> on host 7ba7f815fc28
[2023-10-08T17:09:02.033+0000] {taskinstance.py:1660} INFO - Exporting env vars: AIRFLOW_CTX_DAG_OWNER='airflow' AIRFLOW_CTX_DAG_ID='BigQuery_dag' AIRFLOW_CTX_TASK_ID='Fetch_data_API' AIRFLOW_CTX_EXECUTION_DATE='2023-10-08T17:08:52.450884+00:00' AIRFLOW_CTX_TRY_NUMBER='1' AIRFLOW_CTX_DAG_RUN_ID='manual__2023-10-08T17:08:52.450884+00:00'
[2023-10-08T17:09:02.040+0000] {taskinstance.py:1935} ERROR - Task failed with exception
Traceback (most recent call last):
  File "/home/airflow/.local/lib/python3.8/site-packages/airflow/operators/python.py", line 192, in execute
    return_value = self.execute_callable()
  File "/home/airflow/.local/lib/python3.8/site-packages/airflow/operators/python.py", line 209, in execute_callable
    return self.python_callable(*self.op_args, **self.op_kwargs)
  File "/opt/airflow/dags/BigQuery_dag.py", line 51, in rest_api
    sal = api(URL)
  File "/opt/airflow/dags/BigQuery_dag.py", line 35, in api
    res = response.json()
NameError: name 'response' is not defined
[2023-10-08T17:09:02.084+0000] {taskinstance.py:1398} INFO - Marking task as FAILED. dag_id=BigQuery_dag, task_id=Fetch_data_API, execution_date=20231008T170852, start_date=20231008T170858, end_date=20231008T170902
[2023-10-08T17:09:02.160+0000] {standard_task_runner.py:104} ERROR - Failed to execute job 6 for task Fetch_data_API (name 'response' is not defined; 166)
[2023-10-08T17:09:02.179+0000] {local_task_job_runner.py:228} INFO - Task exited with return code 1
[2023-10-08T17:09:02.223+0000] {taskinstance.py:2776} INFO - 0 downstream tasks scheduled from follow-on schedule check
